<?xml version="1.0"?>
<robot name="ser_robot" xmlns:xacro="http://www.ros.org/wiki/xacro">

	<xacro:macro name="ser_robot_base">
		<link name="base_link">
			<inertial>
      			<origin xyz="-0.016977 0 0.15023" rpy="0 0 0" />
      			<mass value="85.129" />
      			<inertia ixx="2.3039" ixy="8.8263E-07" ixz="0.081061" iyy="3.1872" iyz="-1.0402E-07" izz="3.987" />
    		</inertial>
    		<visual>
      			<origin xyz="0 0 0" rpy="0 0 0" />
      			<geometry>
        			<mesh filename="package://ser_robot_description/meshes/base_link.STL" />
      			</geometry>
      			<material name="base_mat">
        			<color rgba="0.79216 0.81961 0.93333 1" />
      			</material>
   			</visual>
    		<collision>
      			<origin xyz="0 0 0" rpy="0 0 0" />
      			<geometry>
        			<mesh filename="package://ser_robot_description/meshes/base_link.STL" />
      			</geometry>
    		</collision>
  		</link>
  		<link name="laser_Link">
    		<inertial>
      			<origin xyz="0 0 -0.026653" rpy="0 0 0" />
      			<mass value="0.33277" />
      			<inertia ixx="0.00033544" ixy="0" ixz="0" iyy="0.00033544" iyz="0" izz="0.00025593" />
    		</inertial>
    		<visual>
      			<origin xyz="0 0 0" rpy="0 0 0" />
      			<geometry>
        			<mesh filename="package://ser_robot_description/meshes/laser_Link.STL" />
      			</geometry>
      			<material name="laser_mat">
        			<color rgba="1 1 1 1" />
      			</material>
    		</visual>
    		<collision>
      			<origin xyz="0 0 0" rpy="0 0 0" />
      			<geometry>
        			<mesh filename="package://ser_robot_description/meshes/laser_Link.STL" />
      			</geometry>
    		</collision>
  		</link>
  		<joint name="laser_joint" type="fixed">
    		<origin xyz="0.27305 0 0.23" rpy="0 0 0" />
    		<parent link="base_link" />
    		<child link="laser_Link" />
    		<axis xyz="0 0 0" />
  		</joint>
  		<link name="left_wheel_Link">
    		<inertial>
      			<origin xyz="0 0 0" rpy="0 0 0" />
      			<mass value="0.15315" />
      			<inertia ixx="7.288E-05" ixy="0" ixz="0" iyy="7.288E-05" iyz="0" izz="0.00012067" />
    		</inertial>
   			<visual>
      			<origin xyz="0 0 0" rpy="0 0 0" />
      			<geometry>
        			<mesh filename="package://ser_robot_description/meshes/left_wheel_Link.STL" />
      			</geometry>
      			<material name="left_mat">
        			<color rgba="1 1 1 1" />
      			</material>
    		</visual>
    		<collision>
      			<origin xyz="0 0 0" rpy="0 0 0" />
      			<geometry>
       		 		<mesh filename="package://ser_robot_description/meshes/left_wheel_Link.STL" />
      			</geometry>
    		</collision>
  		</link>
  		<joint name="left_wheel_joint" type="continuous">
    		<origin xyz="0 0.21 0.01" rpy="-1.5708 0 0" />
    		<parent link="base_link" />
    		<child link="left_wheel_Link" />
    		<axis xyz="0 0 1" />
  		</joint>
  		<link name="right_wheel_Link">
    		<inertial>
      			<origin xyz="0 0 0" rpy="0 0 0" />
      			<mass value="0.15315" />
      			<inertia ixx="7.288E-05" ixy="0" ixz="0" iyy="7.288E-05" iyz="0" izz="0.00012067" />
    		</inertial>
    		<visual>
      			<origin xyz="0 0 0" rpy="0 0 0" />
      			<geometry>
        			<mesh filename="package://ser_robot_description/meshes/right_wheel_Link.STL" />
     		 	</geometry>
      			<material name="right_mat">
        			<color rgba="1 1 1 1" />
      			</material>
    		</visual>
    		<collision>
      			<origin xyz="0 0 0" rpy="0 0 0" />
      			<geometry>
        			<mesh filename="package://ser_robot_description/meshes/right_wheel_Link.STL" />
      			</geometry>
    		</collision>
  		</link>
  		<joint name="right_wheel_joint" type="continuous">
    		<origin xyz="0 -0.21 0.01" rpy="-1.5708 0 0" />
    		<parent link="base_link" />
    		<child link="right_wheel_Link" />
    		<axis xyz="0 0 1" />
  		</joint>
  		<link name="front_casr_Link">
    		<inertial>
      			<origin xyz="0 0 0" rpy="0 0 0" />
      			<mass value="0.11027" />
      			<inertia ixx="9.9243E-06" ixy="0" ixz="0" iyy="9.9243E-06" iyz="0" izz="9.9243E-06" />
    		</inertial>
    		<visual>
     	 		<origin xyz="0 0 0" rpy="0 0 0" />
      			<geometry>
        			<mesh filename="package://ser_robot_description/meshes/front_casr_Link.STL" />
      			</geometry>
      			<material name="front_mat">
        			<color rgba="0.52941 0.54902 0.54902 1" />
      			</material>
    		</visual>
    		<collision>
      			<origin xyz="0 0 0" rpy="0 0 0" />
      			<geometry>
        			<mesh filename="package://ser_robot_description/meshes/front_casr_Link.STL" />
      			</geometry>
    		</collision>
  		</link>
  		<joint name="front_cast_joint" type="continuous">
    		<origin xyz="0.27 0 -0.015" rpy="-1.5708 0 0" />
    		<parent link="base_link" />
    		<child link="front_casr_Link" />
    		<axis xyz="0 0 1" />
  		</joint>
  		<link name="back_cast_Link">
    		<inertial>
      			<origin xyz="0 0 0" rpy="0 0 0" />
      			<mass value="0.11027" />
      			<inertia ixx="9.9243E-06" ixy="0" ixz="0" iyy="9.9243E-06" iyz="0" izz="9.9243E-06" />
    		</inertial>
    		<visual>
      			<origin xyz="0 0 0" rpy="0 0 0" />
      			<geometry>
        			<mesh filename="package://ser_robot_description/meshes/back_cast_Link.STL" />
      			</geometry>
      			<material name="back_mat">
        			<color rgba="0.52941 0.54902 0.54902 1" />
      			</material>
    		</visual>
    		<collision>
      			<origin xyz="0 0 0" rpy="0 0 0" />
      			<geometry>
        			<mesh filename="package://ser_robot_description/meshes/back_cast_Link.STL" />
      			</geometry>
    		</collision>
  		</link>
  		<joint name="back_cast_joint" type="continuous">
    		<origin xyz="-0.27 0 -0.015" rpy="-1.5708 0 0" />
    		<parent link="base_link" />
    		<child link="back_cast_Link" />
    		<axis xyz="0 0 1" />
  		</joint>
  		<link name="connect_Link">
    		<inertial>
      			<origin xyz="0 0 0.020255" rpy="0 0 0" />
      			<mass value="1.1271" />
      			<inertia  ixx="0.0037751"  ixy="0" ixz="0" iyy="0.0032979" iyz="0" izz="0.0060587" />
    		</inertial>
    		<visual>
     	 		<origin xyz="0 0 0" rpy="0 0 0" />
      			<geometry>
        			<mesh filename="package://ser_robot_description/meshes/connect_Link.STL" />
      			</geometry>
     			 <material name="connect_mat">
       	 			<color rgba="0.79216 0.81961 0.93333 1" />
      			</material>
    		</visual>
    		<collision>
      			<origin xyz="0 0 0" rpy="0 0 0" />
      			<geometry>
        			<mesh filename="package://ser_robot_description/meshes/connect_Link.STL" />
      			</geometry>
    		</collision>
  		</link>
  		<joint name="connect_joint" type="fixed">
    		<origin xyz="0.095 0 0.369" rpy="0 0 0" />
    		<parent link="base_link" />
    		<child link="connect_Link" />
    		<axis xyz="0 0 0" />
  		</joint>
		<!-- ZEDcamera center -->
  		<link name="zed_camera_center">
    		<inertial>
      			<origin xyz="0 0 0" rpy="0 0 0" />
      			<mass value="0.13706" />
      			<inertia ixx="1.8345E-05" ixy="0" ixz="0" iyy="0.00033851" iyz="0" izz="0.00033629" />
    		</inertial>
    		<visual>
      			<origin xyz="0 0 0" rpy="0 0 0" />
      			<geometry>
        			<mesh filename="package://ser_robot_description/meshes/ZED.stl" />
      			</geometry>
      			<material name="zed_mate">
        			<color rgba="1 1 1 1" />
      			</material>
    		</visual>
    		<collision>
      			<origin xyz="0 0 0" rpy="0 0 0" />
      			<geometry>
        			<mesh filename="package://ser_robot_description/meshes/ZED.stl" />
     	 		</geometry>
    		</collision>
  		</link>
  		<!--joint name="zed_joint" type="fixed">
    		<origin xyz="0.245 0 0.6665" rpy="0 0 0" />
    		<parent link="base_link" />
    		<child link="zed_camera_center" />
    		<axis xyz="0 0 0" />
  		</joint-->
      <joint name="zed_joint" type="fixed">
    		<origin xyz="0.245 0 0.6665" rpy="0 0 0" />
    		<parent link="base_link" />
    		<child link="zed_camera_center" />
    		<axis xyz="0 0 0" />
  		</joint>
		<!-- Left Camera -->
		<joint name="zed_left_camera_joint" type="fixed">
        	<parent link="zed_camera_center"/>
        	<child link="zed_left_camera_frame"/>
        	<origin xyz="0 0.06 0" rpy="0 0 0" />
    	</joint>

    	<link name="zed_left_camera_frame" />

    	<joint name="zed_left_camera_optical_joint" type="fixed">
        	<origin xyz="0 0 0" rpy="-1.57079632679 0.0 -1.57079632679"/>
        	<parent link="zed_left_camera_frame"/>
        	<child link="zed_left_camera_optical_frame"/>
    	</joint>

    	<link name="zed_left_camera_optical_frame"/>
		<!-- Right Camera -->
		<joint name="zed_right_camera_joint" type="fixed">
        	<parent link="zed_camera_center"/>
        	<child link="zed_right_camera_frame"/>
        	<origin xyz="0 -0.06 0" rpy="0 0 0" />
    	</joint>

    	<link name="zed_right_camera_frame" />

    	<joint name="zed_right_camera_optical_joint" type="fixed">
        	<origin xyz="0 0 0" rpy="-1.57079632679 0.0 -1.57079632679"/>
        	<parent link="zed_right_camera_frame"/>
        	<child link="zed_right_camera_optical_frame"/>
    	</joint>

    	<link name="zed_right_camera_optical_frame"/>

		<link name="securityroom_Link">
    		<inertial>
      			<origin xyz="0.03 0 0.252" rpy="0 0 0" />
      			<mass value="1.9872" />
      			<inertia ixx="0.0766937554434782" ixy="0" ixz="0" iyy="0.0337313554434782" iyz="0" izz="0.04415472" />
    		</inertial>
    		<visual>
      			<origin xyz="0 0 0" rpy="0 0 0" />
      			<geometry>
        			<mesh filename="package://ser_robot_description/meshes/securityroom_Link.STL" />
      			</geometry>
      			<material name="security_mat">
        			<color rgba="1 1 1 0.3" />
      			</material>
   			</visual>
    		<collision>
      			<origin xyz="0 0 0" rpy="0 0 0" />
      			<geometry>
        			<mesh filename="package://ser_robot_description/meshes/securityroom_Link.STL" />
      			</geometry>
    		</collision>
  		</link>
  		<joint name="securityroom_joint" type="fixed">
    		<origin xyz="0.23 0 0.312" rpy="0 0 0" />
    		<parent link="base_link" />
    		<child link="securityroom_Link" />
    		<axis xyz="0 0 0" />
  		</joint>
	</xacro:macro>
</robot>
